{
 "cells": [
  {
   "cell_type": "code",
   "execution_count": 1,
   "metadata": {},
   "outputs": [],
   "source": [
    "from selenium import webdriver\n",
    "from selenium import webdriver # driver de selenium\n",
    "from webdriver_manager.chrome import ChromeDriverManager\n",
    "from selenium.webdriver.common.by import By   # para buscar segun tag, id, class, etc...\n",
    "import time   # pa%pip install requestsra manejar tiempo\n",
    "from selenium.webdriver.chrome.options import Options\n",
    "from selenium.webdriver.support.ui import WebDriverWait   # es para esperar\n",
    "from selenium.webdriver.support import expected_conditions as EC  # condiciones esperadas...\n",
    "from selenium.webdriver import ActionChains as AC   # acciones encadenadas, rollo doble click\n",
    "from selenium.webdriver.common.action_chains import ActionChains\n",
    "from selenium.webdriver.common.keys import Keys  # manejar teclas\n",
    "import pandas as pd\n",
    "\n",
    "\n",
    "import asyncio\n",
    "\n",
    "\n",
    "from joblib import Parallel, delayed\n",
    "\n",
    "from tqdm.notebook import tqdm\n",
    "\n",
    "\n",
    "import warnings\n",
    "warnings.filterwarnings('ignore')\n",
    "\n",
    "\n",
    "pd.set_option('display.max_columns',None)\n",
    "pd.set_option('display.max_rows',None)\n"
   ]
  },
  {
   "cell_type": "code",
   "execution_count": 2,
   "metadata": {},
   "outputs": [],
   "source": [
    "PATH=ChromeDriverManager().install() \n"
   ]
  },
  {
   "cell_type": "markdown",
   "metadata": {},
   "source": [
    "###Descargar con selenium info de la pagina de la carrera del utmb"
   ]
  },
  {
   "cell_type": "code",
   "execution_count": 16,
   "metadata": {},
   "outputs": [],
   "source": [
    "##Accedemos a una tabla de resultados y la descargamos\n",
    "\n",
    "\n",
    "driver=webdriver.Chrome(PATH) \n",
    "utmb_url='https://utmbmontblanc.com/es/page/107/107.html'\n",
    "driver.get(utmb_url) \n",
    "tabla=driver.find_element(By.XPATH, '//*[@id=\"ct107\"]/div[2]/div[2]/div[2]/span[2]/input').click()\n",
    "\n",
    "time.sleep(2)\n",
    "\n",
    "element= driver.find_element(By.TAG_NAME,'table')\n",
    "\n",
    "filas=element.find_elements(By.TAG_NAME,'tr')\n",
    "\n",
    "data=[]\n",
    "\n",
    "for f in filas:\n",
    "    \n",
    "    elemen=f.find_elements(By.TAG_NAME, 'td')\n",
    "    \n",
    "    tmp=[]\n",
    "    \n",
    "    for e in elemen:\n",
    "        \n",
    "        tmp.append(e.text)\n",
    "        \n",
    "    data.append(tmp)\n",
    "\n",
    "    \n",
    "df=pd.DataFrame(data)\n",
    "#time.sleep(2)\n",
    "#for fila in filas:\n",
    "#    print(fila.text)\n",
    "\n",
    "\n",
    "time.sleep(2)\n",
    "#driver.get(utmb_url) "
   ]
  },
  {
   "cell_type": "code",
   "execution_count": 3,
   "metadata": {},
   "outputs": [],
   "source": [
    "##Ejecutamos la función asincrona\n",
    "\n",
    "def asincrono(funcion):\n",
    "    \n",
    "    def eventos(*args, **kwargs):\n",
    "        return asyncio.get_event_loop().run_in_executor(None, funcion, *args, **kwargs)\n",
    "    \n",
    "    return eventos"
   ]
  },
  {
   "cell_type": "code",
   "execution_count": 13,
   "metadata": {},
   "outputs": [],
   "source": [
    "##Creamos una función para intentar descargarnos todos los resultados de varios años a la vez\n",
    "\n",
    "def utmb(i):  #i es el número de la tabla que n os queremos descargar\n",
    "    PATH=ChromeDriverManager().install()\n",
    "    driver=webdriver.Chrome(PATH) \n",
    "    utmb_url='https://utmbmontblanc.com/es/page/107/107.html'\n",
    "    driver.get(utmb_url) \n",
    "    \n",
    "    try:\n",
    "       \n",
    "        tabla=driver.find_element(By.XPATH, f'//*[@id=\"ct107\"]/div[2]/div[{i}]/div[2]/span[2]/input').click()\n",
    "\n",
    "        time.sleep(2)\n",
    "\n",
    "        element= driver.find_element(By.TAG_NAME,'table')\n",
    "\n",
    "        filas=element.find_elements(By.TAG_NAME,'tr')\n",
    "\n",
    "        data=[]\n",
    "\n",
    "        for f in filas:\n",
    "                \n",
    "            elemen=f.find_elements(By.TAG_NAME, 'td')\n",
    "                \n",
    "            tmp=[]\n",
    "                \n",
    "            for e in elemen:\n",
    "                    \n",
    "                tmp.append(e.text)\n",
    "                    \n",
    "            data.append(tmp)\n",
    "        driver.quit()\n",
    "        return pd.DataFrame(data)\n",
    "    except:\n",
    "        print(f'error en punto{i}')\n",
    "    \n",
    "\n",
    "        \n",
    "##Intentamos en varias ocasiones descagarla de forma asincrona pero da errorr asi que la descargamos de una en una    "
   ]
  },
  {
   "cell_type": "code",
   "execution_count": 4,
   "metadata": {},
   "outputs": [],
   "source": [
    "\n",
    "#lst_df=Parallel(n_jobs=4, verbose=True)(delayed(utmb)(num) for num in range(2,19))\n",
    "\n",
    "\n",
    "\n",
    "    "
   ]
  },
  {
   "cell_type": "code",
   "execution_count": 14,
   "metadata": {},
   "outputs": [
    {
     "name": "stderr",
     "output_type": "stream",
     "text": [
      "Future exception was never retrieved\n",
      "future: <Future finished exception=WebDriverException()>\n",
      "Traceback (most recent call last):\n",
      "  File \"c:\\Users\\sersu\\anaconda3\\lib\\concurrent\\futures\\thread.py\", line 58, in run\n",
      "    result = self.fn(*self.args, **self.kwargs)\n",
      "  File \"C:\\Users\\sersu\\AppData\\Local\\Temp\\ipykernel_32012\\300363245.py\", line 7, in utmb\n",
      "    driver.get(utmb_url)\n",
      "  File \"c:\\Users\\sersu\\anaconda3\\lib\\site-packages\\selenium\\webdriver\\remote\\webdriver.py\", line 455, in get\n",
      "    self.execute(Command.GET, {\"url\": url})\n",
      "  File \"c:\\Users\\sersu\\anaconda3\\lib\\site-packages\\selenium\\webdriver\\remote\\webdriver.py\", line 444, in execute\n",
      "    self.error_handler.check_response(response)\n",
      "  File \"c:\\Users\\sersu\\anaconda3\\lib\\site-packages\\selenium\\webdriver\\remote\\errorhandler.py\", line 249, in check_response\n",
      "    raise exception_class(message, screen, stacktrace)\n",
      "selenium.common.exceptions.WebDriverException: Message: target frame detached\n",
      "  (failed to check if window was closed: disconnected: Unable to receive message from renderer)\n",
      "  (Session info: chrome=107.0.5304.107)\n",
      "Stacktrace:\n",
      "Backtrace:\n",
      "\tOrdinal0 [0x00ABACD3+2075859]\n",
      "\tOrdinal0 [0x00A4EE61+1633889]\n",
      "\tOrdinal0 [0x0094B680+571008]\n",
      "\tOrdinal0 [0x0093E1B4+516532]\n",
      "\tOrdinal0 [0x0093D0A3+512163]\n",
      "\tOrdinal0 [0x0093D6D8+513752]\n",
      "\tOrdinal0 [0x00946662+550498]\n",
      "\tOrdinal0 [0x00951BD5+596949]\n",
      "\tOrdinal0 [0x00954FC0+610240]\n",
      "\tOrdinal0 [0x0093DA81+514689]\n",
      "\tOrdinal0 [0x0095185D+596061]\n",
      "\tOrdinal0 [0x009AB93B+964923]\n",
      "\tOrdinal0 [0x00997136+880950]\n",
      "\tOrdinal0 [0x0096FEFD+720637]\n",
      "\tOrdinal0 [0x00970F3F+724799]\n",
      "\tGetHandleVerifier [0x00D6EED2+2769538]\n",
      "\tGetHandleVerifier [0x00D60D95+2711877]\n",
      "\tGetHandleVerifier [0x00B4A03A+521194]\n",
      "\tGetHandleVerifier [0x00B48DA0+516432]\n",
      "\tOrdinal0 [0x00A5682C+1665068]\n",
      "\tOrdinal0 [0x00A5B128+1683752]\n",
      "\tOrdinal0 [0x00A5B215+1683989]\n",
      "\tOrdinal0 [0x00A66484+1729668]\n",
      "\tBaseThreadInitThunk [0x769B7BA9+25]\n",
      "\tRtlInitializeExceptionChain [0x77C9BB9B+107]\n",
      "\tRtlClearBits [0x77C9BB1F+191]\n",
      "\n"
     ]
    },
    {
     "name": "stdout",
     "output_type": "stream",
     "text": [
      "error en punto3\n",
      "error en punto4\n"
     ]
    },
    {
     "name": "stderr",
     "output_type": "stream",
     "text": [
      "Future exception was never retrieved\n",
      "future: <Future finished exception=WebDriverException()>\n",
      "Traceback (most recent call last):\n",
      "  File \"c:\\Users\\sersu\\anaconda3\\lib\\concurrent\\futures\\thread.py\", line 58, in run\n",
      "    result = self.fn(*self.args, **self.kwargs)\n",
      "  File \"C:\\Users\\sersu\\AppData\\Local\\Temp\\ipykernel_32012\\300363245.py\", line 7, in utmb\n",
      "    driver.get(utmb_url)\n",
      "  File \"c:\\Users\\sersu\\anaconda3\\lib\\site-packages\\selenium\\webdriver\\remote\\webdriver.py\", line 455, in get\n",
      "    self.execute(Command.GET, {\"url\": url})\n",
      "  File \"c:\\Users\\sersu\\anaconda3\\lib\\site-packages\\selenium\\webdriver\\remote\\webdriver.py\", line 444, in execute\n",
      "    self.error_handler.check_response(response)\n",
      "  File \"c:\\Users\\sersu\\anaconda3\\lib\\site-packages\\selenium\\webdriver\\remote\\errorhandler.py\", line 249, in check_response\n",
      "    raise exception_class(message, screen, stacktrace)\n",
      "selenium.common.exceptions.WebDriverException: Message: disconnected: received Inspector.detached event\n",
      "  (failed to check if window was closed: disconnected: Unable to receive message from renderer)\n",
      "  (Session info: chrome=107.0.5304.107)\n",
      "Stacktrace:\n",
      "Backtrace:\n",
      "\tOrdinal0 [0x00ABACD3+2075859]\n",
      "\tOrdinal0 [0x00A4EE61+1633889]\n",
      "\tOrdinal0 [0x0094B7BD+571325]\n",
      "\tOrdinal0 [0x0093F289+520841]\n",
      "\tOrdinal0 [0x0093EEFB+519931]\n",
      "\tOrdinal0 [0x0093E2EB+516843]\n",
      "\tOrdinal0 [0x0093E231+516657]\n",
      "\tOrdinal0 [0x0093DB36+514870]\n",
      "\tOrdinal0 [0x0095185D+596061]\n",
      "\tOrdinal0 [0x009AB93B+964923]\n",
      "\tOrdinal0 [0x00997136+880950]\n",
      "\tOrdinal0 [0x0096FEFD+720637]\n",
      "\tOrdinal0 [0x00970F3F+724799]\n",
      "\tGetHandleVerifier [0x00D6EED2+2769538]\n",
      "\tGetHandleVerifier [0x00D60D95+2711877]\n",
      "\tGetHandleVerifier [0x00B4A03A+521194]\n",
      "\tGetHandleVerifier [0x00B48DA0+516432]\n",
      "\tOrdinal0 [0x00A5682C+1665068]\n",
      "\tOrdinal0 [0x00A5B128+1683752]\n",
      "\tOrdinal0 [0x00A5B215+1683989]\n",
      "\tOrdinal0 [0x00A66484+1729668]\n",
      "\tBaseThreadInitThunk [0x769B7BA9+25]\n",
      "\tRtlInitializeExceptionChain [0x77C9BB9B+107]\n",
      "\tRtlClearBits [0x77C9BB1F+191]\n",
      "\n",
      "Future exception was never retrieved\n",
      "future: <Future finished exception=ProtocolError('Connection aborted.', ConnectionResetError(10054, 'Se ha forzado la interrupción de una conexión existente por el host remoto', None, 10054, None))>\n",
      "Traceback (most recent call last):\n",
      "  File \"c:\\Users\\sersu\\anaconda3\\lib\\site-packages\\urllib3\\connectionpool.py\", line 703, in urlopen\n",
      "    httplib_response = self._make_request(\n",
      "  File \"c:\\Users\\sersu\\anaconda3\\lib\\site-packages\\urllib3\\connectionpool.py\", line 449, in _make_request\n",
      "    six.raise_from(e, None)\n",
      "  File \"<string>\", line 3, in raise_from\n",
      "  File \"c:\\Users\\sersu\\anaconda3\\lib\\site-packages\\urllib3\\connectionpool.py\", line 444, in _make_request\n",
      "    httplib_response = conn.getresponse()\n",
      "  File \"c:\\Users\\sersu\\anaconda3\\lib\\http\\client.py\", line 1377, in getresponse\n",
      "    response.begin()\n",
      "  File \"c:\\Users\\sersu\\anaconda3\\lib\\http\\client.py\", line 320, in begin\n",
      "    version, status, reason = self._read_status()\n",
      "  File \"c:\\Users\\sersu\\anaconda3\\lib\\http\\client.py\", line 281, in _read_status\n",
      "    line = str(self.fp.readline(_MAXLINE + 1), \"iso-8859-1\")\n",
      "  File \"c:\\Users\\sersu\\anaconda3\\lib\\socket.py\", line 704, in readinto\n",
      "    return self._sock.recv_into(b)\n",
      "ConnectionResetError: [WinError 10054] Se ha forzado la interrupción de una conexión existente por el host remoto\n",
      "\n",
      "During handling of the above exception, another exception occurred:\n",
      "\n",
      "Traceback (most recent call last):\n",
      "  File \"c:\\Users\\sersu\\anaconda3\\lib\\concurrent\\futures\\thread.py\", line 58, in run\n",
      "    result = self.fn(*self.args, **self.kwargs)\n",
      "  File \"C:\\Users\\sersu\\AppData\\Local\\Temp\\ipykernel_32012\\300363245.py\", line 7, in utmb\n",
      "    driver.get(utmb_url)\n",
      "  File \"c:\\Users\\sersu\\anaconda3\\lib\\site-packages\\selenium\\webdriver\\remote\\webdriver.py\", line 455, in get\n",
      "    self.execute(Command.GET, {\"url\": url})\n",
      "  File \"c:\\Users\\sersu\\anaconda3\\lib\\site-packages\\selenium\\webdriver\\remote\\webdriver.py\", line 442, in execute\n",
      "    response = self.command_executor.execute(driver_command, params)\n",
      "  File \"c:\\Users\\sersu\\anaconda3\\lib\\site-packages\\selenium\\webdriver\\remote\\remote_connection.py\", line 294, in execute\n",
      "    return self._request(command_info[0], url, body=data)\n",
      "  File \"c:\\Users\\sersu\\anaconda3\\lib\\site-packages\\selenium\\webdriver\\remote\\remote_connection.py\", line 316, in _request\n",
      "    response = self._conn.request(method, url, body=body, headers=headers)\n",
      "  File \"c:\\Users\\sersu\\anaconda3\\lib\\site-packages\\urllib3\\request.py\", line 78, in request\n",
      "    return self.request_encode_body(\n",
      "  File \"c:\\Users\\sersu\\anaconda3\\lib\\site-packages\\urllib3\\request.py\", line 170, in request_encode_body\n",
      "    return self.urlopen(method, url, **extra_kw)\n",
      "  File \"c:\\Users\\sersu\\anaconda3\\lib\\site-packages\\urllib3\\poolmanager.py\", line 376, in urlopen\n",
      "    response = conn.urlopen(method, u.request_uri, **kw)\n",
      "  File \"c:\\Users\\sersu\\anaconda3\\lib\\site-packages\\urllib3\\connectionpool.py\", line 785, in urlopen\n",
      "    retries = retries.increment(\n",
      "  File \"c:\\Users\\sersu\\anaconda3\\lib\\site-packages\\urllib3\\util\\retry.py\", line 550, in increment\n",
      "    raise six.reraise(type(error), error, _stacktrace)\n",
      "  File \"c:\\Users\\sersu\\anaconda3\\lib\\site-packages\\urllib3\\packages\\six.py\", line 769, in reraise\n",
      "    raise value.with_traceback(tb)\n",
      "  File \"c:\\Users\\sersu\\anaconda3\\lib\\site-packages\\urllib3\\connectionpool.py\", line 703, in urlopen\n",
      "    httplib_response = self._make_request(\n",
      "  File \"c:\\Users\\sersu\\anaconda3\\lib\\site-packages\\urllib3\\connectionpool.py\", line 449, in _make_request\n",
      "    six.raise_from(e, None)\n",
      "  File \"<string>\", line 3, in raise_from\n",
      "  File \"c:\\Users\\sersu\\anaconda3\\lib\\site-packages\\urllib3\\connectionpool.py\", line 444, in _make_request\n",
      "    httplib_response = conn.getresponse()\n",
      "  File \"c:\\Users\\sersu\\anaconda3\\lib\\http\\client.py\", line 1377, in getresponse\n",
      "    response.begin()\n",
      "  File \"c:\\Users\\sersu\\anaconda3\\lib\\http\\client.py\", line 320, in begin\n",
      "    version, status, reason = self._read_status()\n",
      "  File \"c:\\Users\\sersu\\anaconda3\\lib\\http\\client.py\", line 281, in _read_status\n",
      "    line = str(self.fp.readline(_MAXLINE + 1), \"iso-8859-1\")\n",
      "  File \"c:\\Users\\sersu\\anaconda3\\lib\\socket.py\", line 704, in readinto\n",
      "    return self._sock.recv_into(b)\n",
      "urllib3.exceptions.ProtocolError: ('Connection aborted.', ConnectionResetError(10054, 'Se ha forzado la interrupción de una conexión existente por el host remoto', None, 10054, None))\n",
      "Future exception was never retrieved\n",
      "future: <Future finished exception=ProtocolError('Connection aborted.', ConnectionResetError(10054, 'Se ha forzado la interrupción de una conexión existente por el host remoto', None, 10054, None))>\n",
      "Traceback (most recent call last):\n",
      "  File \"c:\\Users\\sersu\\anaconda3\\lib\\site-packages\\urllib3\\connectionpool.py\", line 703, in urlopen\n",
      "    httplib_response = self._make_request(\n",
      "  File \"c:\\Users\\sersu\\anaconda3\\lib\\site-packages\\urllib3\\connectionpool.py\", line 449, in _make_request\n",
      "    six.raise_from(e, None)\n",
      "  File \"<string>\", line 3, in raise_from\n",
      "  File \"c:\\Users\\sersu\\anaconda3\\lib\\site-packages\\urllib3\\connectionpool.py\", line 444, in _make_request\n",
      "    httplib_response = conn.getresponse()\n",
      "  File \"c:\\Users\\sersu\\anaconda3\\lib\\http\\client.py\", line 1377, in getresponse\n",
      "    response.begin()\n",
      "  File \"c:\\Users\\sersu\\anaconda3\\lib\\http\\client.py\", line 320, in begin\n",
      "    version, status, reason = self._read_status()\n",
      "  File \"c:\\Users\\sersu\\anaconda3\\lib\\http\\client.py\", line 281, in _read_status\n",
      "    line = str(self.fp.readline(_MAXLINE + 1), \"iso-8859-1\")\n",
      "  File \"c:\\Users\\sersu\\anaconda3\\lib\\socket.py\", line 704, in readinto\n",
      "    return self._sock.recv_into(b)\n",
      "ConnectionResetError: [WinError 10054] Se ha forzado la interrupción de una conexión existente por el host remoto\n",
      "\n",
      "During handling of the above exception, another exception occurred:\n",
      "\n",
      "Traceback (most recent call last):\n",
      "  File \"c:\\Users\\sersu\\anaconda3\\lib\\concurrent\\futures\\thread.py\", line 58, in run\n",
      "    result = self.fn(*self.args, **self.kwargs)\n",
      "  File \"C:\\Users\\sersu\\AppData\\Local\\Temp\\ipykernel_32012\\300363245.py\", line 7, in utmb\n",
      "    driver.get(utmb_url)\n",
      "  File \"c:\\Users\\sersu\\anaconda3\\lib\\site-packages\\selenium\\webdriver\\remote\\webdriver.py\", line 455, in get\n",
      "    self.execute(Command.GET, {\"url\": url})\n",
      "  File \"c:\\Users\\sersu\\anaconda3\\lib\\site-packages\\selenium\\webdriver\\remote\\webdriver.py\", line 442, in execute\n",
      "    response = self.command_executor.execute(driver_command, params)\n",
      "  File \"c:\\Users\\sersu\\anaconda3\\lib\\site-packages\\selenium\\webdriver\\remote\\remote_connection.py\", line 294, in execute\n",
      "    return self._request(command_info[0], url, body=data)\n",
      "  File \"c:\\Users\\sersu\\anaconda3\\lib\\site-packages\\selenium\\webdriver\\remote\\remote_connection.py\", line 316, in _request\n",
      "    response = self._conn.request(method, url, body=body, headers=headers)\n",
      "  File \"c:\\Users\\sersu\\anaconda3\\lib\\site-packages\\urllib3\\request.py\", line 78, in request\n",
      "    return self.request_encode_body(\n",
      "  File \"c:\\Users\\sersu\\anaconda3\\lib\\site-packages\\urllib3\\request.py\", line 170, in request_encode_body\n",
      "    return self.urlopen(method, url, **extra_kw)\n",
      "  File \"c:\\Users\\sersu\\anaconda3\\lib\\site-packages\\urllib3\\poolmanager.py\", line 376, in urlopen\n",
      "    response = conn.urlopen(method, u.request_uri, **kw)\n",
      "  File \"c:\\Users\\sersu\\anaconda3\\lib\\site-packages\\urllib3\\connectionpool.py\", line 785, in urlopen\n",
      "    retries = retries.increment(\n",
      "  File \"c:\\Users\\sersu\\anaconda3\\lib\\site-packages\\urllib3\\util\\retry.py\", line 550, in increment\n",
      "    raise six.reraise(type(error), error, _stacktrace)\n",
      "  File \"c:\\Users\\sersu\\anaconda3\\lib\\site-packages\\urllib3\\packages\\six.py\", line 769, in reraise\n",
      "    raise value.with_traceback(tb)\n",
      "  File \"c:\\Users\\sersu\\anaconda3\\lib\\site-packages\\urllib3\\connectionpool.py\", line 703, in urlopen\n",
      "    httplib_response = self._make_request(\n",
      "  File \"c:\\Users\\sersu\\anaconda3\\lib\\site-packages\\urllib3\\connectionpool.py\", line 449, in _make_request\n",
      "    six.raise_from(e, None)\n",
      "  File \"<string>\", line 3, in raise_from\n",
      "  File \"c:\\Users\\sersu\\anaconda3\\lib\\site-packages\\urllib3\\connectionpool.py\", line 444, in _make_request\n",
      "    httplib_response = conn.getresponse()\n",
      "  File \"c:\\Users\\sersu\\anaconda3\\lib\\http\\client.py\", line 1377, in getresponse\n",
      "    response.begin()\n",
      "  File \"c:\\Users\\sersu\\anaconda3\\lib\\http\\client.py\", line 320, in begin\n",
      "    version, status, reason = self._read_status()\n",
      "  File \"c:\\Users\\sersu\\anaconda3\\lib\\http\\client.py\", line 281, in _read_status\n",
      "    line = str(self.fp.readline(_MAXLINE + 1), \"iso-8859-1\")\n",
      "  File \"c:\\Users\\sersu\\anaconda3\\lib\\socket.py\", line 704, in readinto\n",
      "    return self._sock.recv_into(b)\n",
      "urllib3.exceptions.ProtocolError: ('Connection aborted.', ConnectionResetError(10054, 'Se ha forzado la interrupción de una conexión existente por el host remoto', None, 10054, None))\n",
      "Future exception was never retrieved\n",
      "future: <Future finished exception=ProtocolError('Connection aborted.', ConnectionResetError(10054, 'Se ha forzado la interrupción de una conexión existente por el host remoto', None, 10054, None))>\n",
      "Traceback (most recent call last):\n",
      "  File \"c:\\Users\\sersu\\anaconda3\\lib\\site-packages\\urllib3\\connectionpool.py\", line 703, in urlopen\n",
      "    httplib_response = self._make_request(\n",
      "  File \"c:\\Users\\sersu\\anaconda3\\lib\\site-packages\\urllib3\\connectionpool.py\", line 449, in _make_request\n",
      "    six.raise_from(e, None)\n",
      "  File \"<string>\", line 3, in raise_from\n",
      "  File \"c:\\Users\\sersu\\anaconda3\\lib\\site-packages\\urllib3\\connectionpool.py\", line 444, in _make_request\n",
      "    httplib_response = conn.getresponse()\n",
      "  File \"c:\\Users\\sersu\\anaconda3\\lib\\http\\client.py\", line 1377, in getresponse\n",
      "    response.begin()\n",
      "  File \"c:\\Users\\sersu\\anaconda3\\lib\\http\\client.py\", line 320, in begin\n",
      "    version, status, reason = self._read_status()\n",
      "  File \"c:\\Users\\sersu\\anaconda3\\lib\\http\\client.py\", line 281, in _read_status\n",
      "    line = str(self.fp.readline(_MAXLINE + 1), \"iso-8859-1\")\n",
      "  File \"c:\\Users\\sersu\\anaconda3\\lib\\socket.py\", line 704, in readinto\n",
      "    return self._sock.recv_into(b)\n",
      "ConnectionResetError: [WinError 10054] Se ha forzado la interrupción de una conexión existente por el host remoto\n",
      "\n",
      "During handling of the above exception, another exception occurred:\n",
      "\n",
      "Traceback (most recent call last):\n",
      "  File \"c:\\Users\\sersu\\anaconda3\\lib\\concurrent\\futures\\thread.py\", line 58, in run\n",
      "    result = self.fn(*self.args, **self.kwargs)\n",
      "  File \"C:\\Users\\sersu\\AppData\\Local\\Temp\\ipykernel_32012\\300363245.py\", line 7, in utmb\n",
      "    driver.get(utmb_url)\n",
      "  File \"c:\\Users\\sersu\\anaconda3\\lib\\site-packages\\selenium\\webdriver\\remote\\webdriver.py\", line 455, in get\n",
      "    self.execute(Command.GET, {\"url\": url})\n",
      "  File \"c:\\Users\\sersu\\anaconda3\\lib\\site-packages\\selenium\\webdriver\\remote\\webdriver.py\", line 442, in execute\n",
      "    response = self.command_executor.execute(driver_command, params)\n",
      "  File \"c:\\Users\\sersu\\anaconda3\\lib\\site-packages\\selenium\\webdriver\\remote\\remote_connection.py\", line 294, in execute\n",
      "    return self._request(command_info[0], url, body=data)\n",
      "  File \"c:\\Users\\sersu\\anaconda3\\lib\\site-packages\\selenium\\webdriver\\remote\\remote_connection.py\", line 316, in _request\n",
      "    response = self._conn.request(method, url, body=body, headers=headers)\n",
      "  File \"c:\\Users\\sersu\\anaconda3\\lib\\site-packages\\urllib3\\request.py\", line 78, in request\n",
      "    return self.request_encode_body(\n",
      "  File \"c:\\Users\\sersu\\anaconda3\\lib\\site-packages\\urllib3\\request.py\", line 170, in request_encode_body\n",
      "    return self.urlopen(method, url, **extra_kw)\n",
      "  File \"c:\\Users\\sersu\\anaconda3\\lib\\site-packages\\urllib3\\poolmanager.py\", line 376, in urlopen\n",
      "    response = conn.urlopen(method, u.request_uri, **kw)\n",
      "  File \"c:\\Users\\sersu\\anaconda3\\lib\\site-packages\\urllib3\\connectionpool.py\", line 785, in urlopen\n",
      "    retries = retries.increment(\n",
      "  File \"c:\\Users\\sersu\\anaconda3\\lib\\site-packages\\urllib3\\util\\retry.py\", line 550, in increment\n",
      "    raise six.reraise(type(error), error, _stacktrace)\n",
      "  File \"c:\\Users\\sersu\\anaconda3\\lib\\site-packages\\urllib3\\packages\\six.py\", line 769, in reraise\n",
      "    raise value.with_traceback(tb)\n",
      "  File \"c:\\Users\\sersu\\anaconda3\\lib\\site-packages\\urllib3\\connectionpool.py\", line 703, in urlopen\n",
      "    httplib_response = self._make_request(\n",
      "  File \"c:\\Users\\sersu\\anaconda3\\lib\\site-packages\\urllib3\\connectionpool.py\", line 449, in _make_request\n",
      "    six.raise_from(e, None)\n",
      "  File \"<string>\", line 3, in raise_from\n",
      "  File \"c:\\Users\\sersu\\anaconda3\\lib\\site-packages\\urllib3\\connectionpool.py\", line 444, in _make_request\n",
      "    httplib_response = conn.getresponse()\n",
      "  File \"c:\\Users\\sersu\\anaconda3\\lib\\http\\client.py\", line 1377, in getresponse\n",
      "    response.begin()\n",
      "  File \"c:\\Users\\sersu\\anaconda3\\lib\\http\\client.py\", line 320, in begin\n",
      "    version, status, reason = self._read_status()\n",
      "  File \"c:\\Users\\sersu\\anaconda3\\lib\\http\\client.py\", line 281, in _read_status\n",
      "    line = str(self.fp.readline(_MAXLINE + 1), \"iso-8859-1\")\n",
      "  File \"c:\\Users\\sersu\\anaconda3\\lib\\socket.py\", line 704, in readinto\n",
      "    return self._sock.recv_into(b)\n",
      "urllib3.exceptions.ProtocolError: ('Connection aborted.', ConnectionResetError(10054, 'Se ha forzado la interrupción de una conexión existente por el host remoto', None, 10054, None))\n",
      "Future exception was never retrieved\n",
      "future: <Future finished exception=ProtocolError('Connection aborted.', ConnectionResetError(10054, 'Se ha forzado la interrupción de una conexión existente por el host remoto', None, 10054, None))>\n",
      "Traceback (most recent call last):\n",
      "  File \"c:\\Users\\sersu\\anaconda3\\lib\\site-packages\\urllib3\\connectionpool.py\", line 703, in urlopen\n",
      "    httplib_response = self._make_request(\n",
      "  File \"c:\\Users\\sersu\\anaconda3\\lib\\site-packages\\urllib3\\connectionpool.py\", line 449, in _make_request\n",
      "    six.raise_from(e, None)\n",
      "  File \"<string>\", line 3, in raise_from\n",
      "  File \"c:\\Users\\sersu\\anaconda3\\lib\\site-packages\\urllib3\\connectionpool.py\", line 444, in _make_request\n",
      "    httplib_response = conn.getresponse()\n",
      "  File \"c:\\Users\\sersu\\anaconda3\\lib\\http\\client.py\", line 1377, in getresponse\n",
      "    response.begin()\n",
      "  File \"c:\\Users\\sersu\\anaconda3\\lib\\http\\client.py\", line 320, in begin\n",
      "    version, status, reason = self._read_status()\n",
      "  File \"c:\\Users\\sersu\\anaconda3\\lib\\http\\client.py\", line 281, in _read_status\n",
      "    line = str(self.fp.readline(_MAXLINE + 1), \"iso-8859-1\")\n",
      "  File \"c:\\Users\\sersu\\anaconda3\\lib\\socket.py\", line 704, in readinto\n",
      "    return self._sock.recv_into(b)\n",
      "ConnectionResetError: [WinError 10054] Se ha forzado la interrupción de una conexión existente por el host remoto\n",
      "\n",
      "During handling of the above exception, another exception occurred:\n",
      "\n",
      "Traceback (most recent call last):\n",
      "  File \"c:\\Users\\sersu\\anaconda3\\lib\\concurrent\\futures\\thread.py\", line 58, in run\n",
      "    result = self.fn(*self.args, **self.kwargs)\n",
      "  File \"C:\\Users\\sersu\\AppData\\Local\\Temp\\ipykernel_32012\\300363245.py\", line 7, in utmb\n",
      "    driver.get(utmb_url)\n",
      "  File \"c:\\Users\\sersu\\anaconda3\\lib\\site-packages\\selenium\\webdriver\\remote\\webdriver.py\", line 455, in get\n",
      "    self.execute(Command.GET, {\"url\": url})\n",
      "  File \"c:\\Users\\sersu\\anaconda3\\lib\\site-packages\\selenium\\webdriver\\remote\\webdriver.py\", line 442, in execute\n",
      "    response = self.command_executor.execute(driver_command, params)\n",
      "  File \"c:\\Users\\sersu\\anaconda3\\lib\\site-packages\\selenium\\webdriver\\remote\\remote_connection.py\", line 294, in execute\n",
      "    return self._request(command_info[0], url, body=data)\n",
      "  File \"c:\\Users\\sersu\\anaconda3\\lib\\site-packages\\selenium\\webdriver\\remote\\remote_connection.py\", line 316, in _request\n",
      "    response = self._conn.request(method, url, body=body, headers=headers)\n",
      "  File \"c:\\Users\\sersu\\anaconda3\\lib\\site-packages\\urllib3\\request.py\", line 78, in request\n",
      "    return self.request_encode_body(\n",
      "  File \"c:\\Users\\sersu\\anaconda3\\lib\\site-packages\\urllib3\\request.py\", line 170, in request_encode_body\n",
      "    return self.urlopen(method, url, **extra_kw)\n",
      "  File \"c:\\Users\\sersu\\anaconda3\\lib\\site-packages\\urllib3\\poolmanager.py\", line 376, in urlopen\n",
      "    response = conn.urlopen(method, u.request_uri, **kw)\n",
      "  File \"c:\\Users\\sersu\\anaconda3\\lib\\site-packages\\urllib3\\connectionpool.py\", line 785, in urlopen\n",
      "    retries = retries.increment(\n",
      "  File \"c:\\Users\\sersu\\anaconda3\\lib\\site-packages\\urllib3\\util\\retry.py\", line 550, in increment\n",
      "    raise six.reraise(type(error), error, _stacktrace)\n",
      "  File \"c:\\Users\\sersu\\anaconda3\\lib\\site-packages\\urllib3\\packages\\six.py\", line 769, in reraise\n",
      "    raise value.with_traceback(tb)\n",
      "  File \"c:\\Users\\sersu\\anaconda3\\lib\\site-packages\\urllib3\\connectionpool.py\", line 703, in urlopen\n",
      "    httplib_response = self._make_request(\n",
      "  File \"c:\\Users\\sersu\\anaconda3\\lib\\site-packages\\urllib3\\connectionpool.py\", line 449, in _make_request\n",
      "    six.raise_from(e, None)\n",
      "  File \"<string>\", line 3, in raise_from\n",
      "  File \"c:\\Users\\sersu\\anaconda3\\lib\\site-packages\\urllib3\\connectionpool.py\", line 444, in _make_request\n",
      "    httplib_response = conn.getresponse()\n",
      "  File \"c:\\Users\\sersu\\anaconda3\\lib\\http\\client.py\", line 1377, in getresponse\n",
      "    response.begin()\n",
      "  File \"c:\\Users\\sersu\\anaconda3\\lib\\http\\client.py\", line 320, in begin\n",
      "    version, status, reason = self._read_status()\n",
      "  File \"c:\\Users\\sersu\\anaconda3\\lib\\http\\client.py\", line 281, in _read_status\n",
      "    line = str(self.fp.readline(_MAXLINE + 1), \"iso-8859-1\")\n",
      "  File \"c:\\Users\\sersu\\anaconda3\\lib\\socket.py\", line 704, in readinto\n",
      "    return self._sock.recv_into(b)\n",
      "urllib3.exceptions.ProtocolError: ('Connection aborted.', ConnectionResetError(10054, 'Se ha forzado la interrupción de una conexión existente por el host remoto', None, 10054, None))\n"
     ]
    },
    {
     "name": "stdout",
     "output_type": "stream",
     "text": [
      "error en punto10\n"
     ]
    },
    {
     "name": "stderr",
     "output_type": "stream",
     "text": [
      "Future exception was never retrieved\n",
      "future: <Future finished exception=ProtocolError('Connection aborted.', ConnectionResetError(10054, 'Se ha forzado la interrupción de una conexión existente por el host remoto', None, 10054, None))>\n",
      "Traceback (most recent call last):\n",
      "  File \"c:\\Users\\sersu\\anaconda3\\lib\\site-packages\\urllib3\\connectionpool.py\", line 703, in urlopen\n",
      "    httplib_response = self._make_request(\n",
      "  File \"c:\\Users\\sersu\\anaconda3\\lib\\site-packages\\urllib3\\connectionpool.py\", line 449, in _make_request\n",
      "    six.raise_from(e, None)\n",
      "  File \"<string>\", line 3, in raise_from\n",
      "  File \"c:\\Users\\sersu\\anaconda3\\lib\\site-packages\\urllib3\\connectionpool.py\", line 444, in _make_request\n",
      "    httplib_response = conn.getresponse()\n",
      "  File \"c:\\Users\\sersu\\anaconda3\\lib\\http\\client.py\", line 1377, in getresponse\n",
      "    response.begin()\n",
      "  File \"c:\\Users\\sersu\\anaconda3\\lib\\http\\client.py\", line 320, in begin\n",
      "    version, status, reason = self._read_status()\n",
      "  File \"c:\\Users\\sersu\\anaconda3\\lib\\http\\client.py\", line 281, in _read_status\n",
      "    line = str(self.fp.readline(_MAXLINE + 1), \"iso-8859-1\")\n",
      "  File \"c:\\Users\\sersu\\anaconda3\\lib\\socket.py\", line 704, in readinto\n",
      "    return self._sock.recv_into(b)\n",
      "ConnectionResetError: [WinError 10054] Se ha forzado la interrupción de una conexión existente por el host remoto\n",
      "\n",
      "During handling of the above exception, another exception occurred:\n",
      "\n",
      "Traceback (most recent call last):\n",
      "  File \"c:\\Users\\sersu\\anaconda3\\lib\\concurrent\\futures\\thread.py\", line 58, in run\n",
      "    result = self.fn(*self.args, **self.kwargs)\n",
      "  File \"C:\\Users\\sersu\\AppData\\Local\\Temp\\ipykernel_32012\\300363245.py\", line 7, in utmb\n",
      "    driver.get(utmb_url)\n",
      "  File \"c:\\Users\\sersu\\anaconda3\\lib\\site-packages\\selenium\\webdriver\\remote\\webdriver.py\", line 455, in get\n",
      "    self.execute(Command.GET, {\"url\": url})\n",
      "  File \"c:\\Users\\sersu\\anaconda3\\lib\\site-packages\\selenium\\webdriver\\remote\\webdriver.py\", line 442, in execute\n",
      "    response = self.command_executor.execute(driver_command, params)\n",
      "  File \"c:\\Users\\sersu\\anaconda3\\lib\\site-packages\\selenium\\webdriver\\remote\\remote_connection.py\", line 294, in execute\n",
      "    return self._request(command_info[0], url, body=data)\n",
      "  File \"c:\\Users\\sersu\\anaconda3\\lib\\site-packages\\selenium\\webdriver\\remote\\remote_connection.py\", line 316, in _request\n",
      "    response = self._conn.request(method, url, body=body, headers=headers)\n",
      "  File \"c:\\Users\\sersu\\anaconda3\\lib\\site-packages\\urllib3\\request.py\", line 78, in request\n",
      "    return self.request_encode_body(\n",
      "  File \"c:\\Users\\sersu\\anaconda3\\lib\\site-packages\\urllib3\\request.py\", line 170, in request_encode_body\n",
      "    return self.urlopen(method, url, **extra_kw)\n",
      "  File \"c:\\Users\\sersu\\anaconda3\\lib\\site-packages\\urllib3\\poolmanager.py\", line 376, in urlopen\n",
      "    response = conn.urlopen(method, u.request_uri, **kw)\n",
      "  File \"c:\\Users\\sersu\\anaconda3\\lib\\site-packages\\urllib3\\connectionpool.py\", line 785, in urlopen\n",
      "    retries = retries.increment(\n",
      "  File \"c:\\Users\\sersu\\anaconda3\\lib\\site-packages\\urllib3\\util\\retry.py\", line 550, in increment\n",
      "    raise six.reraise(type(error), error, _stacktrace)\n",
      "  File \"c:\\Users\\sersu\\anaconda3\\lib\\site-packages\\urllib3\\packages\\six.py\", line 769, in reraise\n",
      "    raise value.with_traceback(tb)\n",
      "  File \"c:\\Users\\sersu\\anaconda3\\lib\\site-packages\\urllib3\\connectionpool.py\", line 703, in urlopen\n",
      "    httplib_response = self._make_request(\n",
      "  File \"c:\\Users\\sersu\\anaconda3\\lib\\site-packages\\urllib3\\connectionpool.py\", line 449, in _make_request\n",
      "    six.raise_from(e, None)\n",
      "  File \"<string>\", line 3, in raise_from\n",
      "  File \"c:\\Users\\sersu\\anaconda3\\lib\\site-packages\\urllib3\\connectionpool.py\", line 444, in _make_request\n",
      "    httplib_response = conn.getresponse()\n",
      "  File \"c:\\Users\\sersu\\anaconda3\\lib\\http\\client.py\", line 1377, in getresponse\n",
      "    response.begin()\n",
      "  File \"c:\\Users\\sersu\\anaconda3\\lib\\http\\client.py\", line 320, in begin\n",
      "    version, status, reason = self._read_status()\n",
      "  File \"c:\\Users\\sersu\\anaconda3\\lib\\http\\client.py\", line 281, in _read_status\n",
      "    line = str(self.fp.readline(_MAXLINE + 1), \"iso-8859-1\")\n",
      "  File \"c:\\Users\\sersu\\anaconda3\\lib\\socket.py\", line 704, in readinto\n",
      "    return self._sock.recv_into(b)\n",
      "urllib3.exceptions.ProtocolError: ('Connection aborted.', ConnectionResetError(10054, 'Se ha forzado la interrupción de una conexión existente por el host remoto', None, 10054, None))\n",
      "Future exception was never retrieved\n",
      "future: <Future finished exception=WebDriverException()>\n",
      "Traceback (most recent call last):\n",
      "  File \"c:\\Users\\sersu\\anaconda3\\lib\\concurrent\\futures\\thread.py\", line 58, in run\n",
      "    result = self.fn(*self.args, **self.kwargs)\n",
      "  File \"C:\\Users\\sersu\\AppData\\Local\\Temp\\ipykernel_32012\\300363245.py\", line 5, in utmb\n",
      "    driver=webdriver.Chrome(PATH)\n",
      "  File \"c:\\Users\\sersu\\anaconda3\\lib\\site-packages\\selenium\\webdriver\\chrome\\webdriver.py\", line 81, in __init__\n",
      "    super().__init__(\n",
      "  File \"c:\\Users\\sersu\\anaconda3\\lib\\site-packages\\selenium\\webdriver\\chromium\\webdriver.py\", line 106, in __init__\n",
      "    super().__init__(\n",
      "  File \"c:\\Users\\sersu\\anaconda3\\lib\\site-packages\\selenium\\webdriver\\remote\\webdriver.py\", line 288, in __init__\n",
      "    self.start_session(capabilities, browser_profile)\n",
      "  File \"c:\\Users\\sersu\\anaconda3\\lib\\site-packages\\selenium\\webdriver\\remote\\webdriver.py\", line 381, in start_session\n",
      "    response = self.execute(Command.NEW_SESSION, parameters)\n",
      "  File \"c:\\Users\\sersu\\anaconda3\\lib\\site-packages\\selenium\\webdriver\\remote\\webdriver.py\", line 444, in execute\n",
      "    self.error_handler.check_response(response)\n",
      "  File \"c:\\Users\\sersu\\anaconda3\\lib\\site-packages\\selenium\\webdriver\\remote\\errorhandler.py\", line 249, in check_response\n",
      "    raise exception_class(message, screen, stacktrace)\n",
      "selenium.common.exceptions.WebDriverException: Message: disconnected: received Inspector.detached event\n",
      "  (failed to check if window was closed: disconnected: unable to connect to renderer)\n",
      "  (Session info: chrome=107.0.5304.107)\n",
      "Stacktrace:\n",
      "Backtrace:\n",
      "\tOrdinal0 [0x00ABACD3+2075859]\n",
      "\tOrdinal0 [0x00A4EE61+1633889]\n",
      "\tOrdinal0 [0x0094B7BD+571325]\n",
      "\tOrdinal0 [0x0093F289+520841]\n",
      "\tOrdinal0 [0x0093EEFB+519931]\n",
      "\tOrdinal0 [0x0093E2EB+516843]\n",
      "\tOrdinal0 [0x0093E231+516657]\n",
      "\tOrdinal0 [0x0093D0A3+512163]\n",
      "\tOrdinal0 [0x0093D5AD+513453]\n",
      "\tOrdinal0 [0x0093CCB5+511157]\n",
      "\tOrdinal0 [0x00947113+553235]\n",
      "\tOrdinal0 [0x0093CC65+511077]\n",
      "\tOrdinal0 [0x0093DEA6+515750]\n",
      "\tOrdinal0 [0x0093D0A3+512163]\n",
      "\tOrdinal0 [0x0093D5AD+513453]\n",
      "\tOrdinal0 [0x0093CCB5+511157]\n",
      "\tOrdinal0 [0x00944C48+543816]\n",
      "\tOrdinal0 [0x0093CC65+511077]\n",
      "\tOrdinal0 [0x0093DEA6+515750]\n",
      "\tOrdinal0 [0x0093D0A3+512163]\n",
      "\tOrdinal0 [0x0093D5AD+513453]\n",
      "\tOrdinal0 [0x0093CCB5+511157]\n",
      "\tOrdinal0 [0x00942862+534626]\n",
      "\tOrdinal0 [0x0093CC65+511077]\n",
      "\tOrdinal0 [0x0093DEA6+515750]\n",
      "\tOrdinal0 [0x0093D0A3+512163]\n",
      "\tOrdinal0 [0x0093D5AD+513453]\n",
      "\tOrdinal0 [0x0093CCB5+511157]\n",
      "\tOrdinal0 [0x00937F2D+491309]\n",
      "\tOrdinal0 [0x0093CC65+511077]\n",
      "\tOrdinal0 [0x0093C42D+508973]\n",
      "\tOrdinal0 [0x0093C11F+508191]\n",
      "\tOrdinal0 [0x0094CC53+576595]\n",
      "\tOrdinal0 [0x009320E7+467175]\n",
      "\tOrdinal0 [0x0093129B+463515]\n",
      "\tOrdinal0 [0x0099DD7C+908668]\n",
      "\tOrdinal0 [0x0099D6AA+906922]\n",
      "\tOrdinal0 [0x00997136+880950]\n",
      "\tOrdinal0 [0x0096FEFD+720637]\n",
      "\tOrdinal0 [0x00970F3F+724799]\n",
      "\tGetHandleVerifier [0x00D6EED2+2769538]\n",
      "\tGetHandleVerifier [0x00D60D95+2711877]\n",
      "\tGetHandleVerifier [0x00B4A03A+521194]\n",
      "\tGetHandleVerifier [0x00B48DA0+516432]\n",
      "\tOrdinal0 [0x00A5682C+1665068]\n",
      "\tOrdinal0 [0x00A5B128+1683752]\n",
      "\tOrdinal0 [0x00A5B215+1683989]\n",
      "\tOrdinal0 [0x00A66484+1729668]\n",
      "\tBaseThreadInitThunk [0x769B7BA9+25]\n",
      "\tRtlInitializeExceptionChain [0x77C9BB9B+107]\n",
      "\tRtlClearBits [0x77C9BB1F+191]\n",
      "\n",
      "Future exception was never retrieved\n",
      "future: <Future finished exception=ProtocolError('Connection aborted.', ConnectionResetError(10054, 'Se ha forzado la interrupción de una conexión existente por el host remoto', None, 10054, None))>\n",
      "Traceback (most recent call last):\n",
      "  File \"c:\\Users\\sersu\\anaconda3\\lib\\site-packages\\urllib3\\connectionpool.py\", line 703, in urlopen\n",
      "    httplib_response = self._make_request(\n",
      "  File \"c:\\Users\\sersu\\anaconda3\\lib\\site-packages\\urllib3\\connectionpool.py\", line 449, in _make_request\n",
      "    six.raise_from(e, None)\n",
      "  File \"<string>\", line 3, in raise_from\n",
      "  File \"c:\\Users\\sersu\\anaconda3\\lib\\site-packages\\urllib3\\connectionpool.py\", line 444, in _make_request\n",
      "    httplib_response = conn.getresponse()\n",
      "  File \"c:\\Users\\sersu\\anaconda3\\lib\\http\\client.py\", line 1377, in getresponse\n",
      "    response.begin()\n",
      "  File \"c:\\Users\\sersu\\anaconda3\\lib\\http\\client.py\", line 320, in begin\n",
      "    version, status, reason = self._read_status()\n",
      "  File \"c:\\Users\\sersu\\anaconda3\\lib\\http\\client.py\", line 281, in _read_status\n",
      "    line = str(self.fp.readline(_MAXLINE + 1), \"iso-8859-1\")\n",
      "  File \"c:\\Users\\sersu\\anaconda3\\lib\\socket.py\", line 704, in readinto\n",
      "    return self._sock.recv_into(b)\n",
      "ConnectionResetError: [WinError 10054] Se ha forzado la interrupción de una conexión existente por el host remoto\n",
      "\n",
      "During handling of the above exception, another exception occurred:\n",
      "\n",
      "Traceback (most recent call last):\n",
      "  File \"c:\\Users\\sersu\\anaconda3\\lib\\concurrent\\futures\\thread.py\", line 58, in run\n",
      "    result = self.fn(*self.args, **self.kwargs)\n",
      "  File \"C:\\Users\\sersu\\AppData\\Local\\Temp\\ipykernel_32012\\300363245.py\", line 7, in utmb\n",
      "    driver.get(utmb_url)\n",
      "  File \"c:\\Users\\sersu\\anaconda3\\lib\\site-packages\\selenium\\webdriver\\remote\\webdriver.py\", line 455, in get\n",
      "    self.execute(Command.GET, {\"url\": url})\n",
      "  File \"c:\\Users\\sersu\\anaconda3\\lib\\site-packages\\selenium\\webdriver\\remote\\webdriver.py\", line 442, in execute\n",
      "    response = self.command_executor.execute(driver_command, params)\n",
      "  File \"c:\\Users\\sersu\\anaconda3\\lib\\site-packages\\selenium\\webdriver\\remote\\remote_connection.py\", line 294, in execute\n",
      "    return self._request(command_info[0], url, body=data)\n",
      "  File \"c:\\Users\\sersu\\anaconda3\\lib\\site-packages\\selenium\\webdriver\\remote\\remote_connection.py\", line 316, in _request\n",
      "    response = self._conn.request(method, url, body=body, headers=headers)\n",
      "  File \"c:\\Users\\sersu\\anaconda3\\lib\\site-packages\\urllib3\\request.py\", line 78, in request\n",
      "    return self.request_encode_body(\n",
      "  File \"c:\\Users\\sersu\\anaconda3\\lib\\site-packages\\urllib3\\request.py\", line 170, in request_encode_body\n",
      "    return self.urlopen(method, url, **extra_kw)\n",
      "  File \"c:\\Users\\sersu\\anaconda3\\lib\\site-packages\\urllib3\\poolmanager.py\", line 376, in urlopen\n",
      "    response = conn.urlopen(method, u.request_uri, **kw)\n",
      "  File \"c:\\Users\\sersu\\anaconda3\\lib\\site-packages\\urllib3\\connectionpool.py\", line 785, in urlopen\n",
      "    retries = retries.increment(\n",
      "  File \"c:\\Users\\sersu\\anaconda3\\lib\\site-packages\\urllib3\\util\\retry.py\", line 550, in increment\n",
      "    raise six.reraise(type(error), error, _stacktrace)\n",
      "  File \"c:\\Users\\sersu\\anaconda3\\lib\\site-packages\\urllib3\\packages\\six.py\", line 769, in reraise\n",
      "    raise value.with_traceback(tb)\n",
      "  File \"c:\\Users\\sersu\\anaconda3\\lib\\site-packages\\urllib3\\connectionpool.py\", line 703, in urlopen\n",
      "    httplib_response = self._make_request(\n",
      "  File \"c:\\Users\\sersu\\anaconda3\\lib\\site-packages\\urllib3\\connectionpool.py\", line 449, in _make_request\n",
      "    six.raise_from(e, None)\n",
      "  File \"<string>\", line 3, in raise_from\n",
      "  File \"c:\\Users\\sersu\\anaconda3\\lib\\site-packages\\urllib3\\connectionpool.py\", line 444, in _make_request\n",
      "    httplib_response = conn.getresponse()\n",
      "  File \"c:\\Users\\sersu\\anaconda3\\lib\\http\\client.py\", line 1377, in getresponse\n",
      "    response.begin()\n",
      "  File \"c:\\Users\\sersu\\anaconda3\\lib\\http\\client.py\", line 320, in begin\n",
      "    version, status, reason = self._read_status()\n",
      "  File \"c:\\Users\\sersu\\anaconda3\\lib\\http\\client.py\", line 281, in _read_status\n",
      "    line = str(self.fp.readline(_MAXLINE + 1), \"iso-8859-1\")\n",
      "  File \"c:\\Users\\sersu\\anaconda3\\lib\\socket.py\", line 704, in readinto\n",
      "    return self._sock.recv_into(b)\n",
      "urllib3.exceptions.ProtocolError: ('Connection aborted.', ConnectionResetError(10054, 'Se ha forzado la interrupción de una conexión existente por el host remoto', None, 10054, None))\n",
      "Future exception was never retrieved\n",
      "future: <Future finished exception=WebDriverException()>\n",
      "Traceback (most recent call last):\n",
      "  File \"c:\\Users\\sersu\\anaconda3\\lib\\concurrent\\futures\\thread.py\", line 58, in run\n",
      "    result = self.fn(*self.args, **self.kwargs)\n",
      "  File \"C:\\Users\\sersu\\AppData\\Local\\Temp\\ipykernel_32012\\300363245.py\", line 5, in utmb\n",
      "    driver=webdriver.Chrome(PATH)\n",
      "  File \"c:\\Users\\sersu\\anaconda3\\lib\\site-packages\\selenium\\webdriver\\chrome\\webdriver.py\", line 81, in __init__\n",
      "    super().__init__(\n",
      "  File \"c:\\Users\\sersu\\anaconda3\\lib\\site-packages\\selenium\\webdriver\\chromium\\webdriver.py\", line 106, in __init__\n",
      "    super().__init__(\n",
      "  File \"c:\\Users\\sersu\\anaconda3\\lib\\site-packages\\selenium\\webdriver\\remote\\webdriver.py\", line 288, in __init__\n",
      "    self.start_session(capabilities, browser_profile)\n",
      "  File \"c:\\Users\\sersu\\anaconda3\\lib\\site-packages\\selenium\\webdriver\\remote\\webdriver.py\", line 381, in start_session\n",
      "    response = self.execute(Command.NEW_SESSION, parameters)\n",
      "  File \"c:\\Users\\sersu\\anaconda3\\lib\\site-packages\\selenium\\webdriver\\remote\\webdriver.py\", line 444, in execute\n",
      "    self.error_handler.check_response(response)\n",
      "  File \"c:\\Users\\sersu\\anaconda3\\lib\\site-packages\\selenium\\webdriver\\remote\\errorhandler.py\", line 249, in check_response\n",
      "    raise exception_class(message, screen, stacktrace)\n",
      "selenium.common.exceptions.WebDriverException: Message: unknown error: Chrome failed to start: exited normally.\n",
      "  (chrome not reachable)\n",
      "  (The process started from chrome location C:\\Program Files\\Google\\Chrome\\Application\\chrome.exe is no longer running, so ChromeDriver is assuming that Chrome has crashed.)\n",
      "Stacktrace:\n",
      "Backtrace:\n",
      "\tOrdinal0 [0x00ABACD3+2075859]\n",
      "\tOrdinal0 [0x00A4EE61+1633889]\n",
      "\tOrdinal0 [0x0094B7BD+571325]\n",
      "\tOrdinal0 [0x0096AA93+699027]\n",
      "\tOrdinal0 [0x00966BE9+682985]\n",
      "\tOrdinal0 [0x0099DBD3+908243]\n",
      "\tOrdinal0 [0x0099D6AA+906922]\n",
      "\tOrdinal0 [0x00997136+880950]\n",
      "\tOrdinal0 [0x0096FEFD+720637]\n",
      "\tOrdinal0 [0x00970F3F+724799]\n",
      "\tGetHandleVerifier [0x00D6EED2+2769538]\n",
      "\tGetHandleVerifier [0x00D60D95+2711877]\n",
      "\tGetHandleVerifier [0x00B4A03A+521194]\n",
      "\tGetHandleVerifier [0x00B48DA0+516432]\n",
      "\tOrdinal0 [0x00A5682C+1665068]\n",
      "\tOrdinal0 [0x00A5B128+1683752]\n",
      "\tOrdinal0 [0x00A5B215+1683989]\n",
      "\tOrdinal0 [0x00A66484+1729668]\n",
      "\tBaseThreadInitThunk [0x769B7BA9+25]\n",
      "\tRtlInitializeExceptionChain [0x77C9BB9B+107]\n",
      "\tRtlClearBits [0x77C9BB1F+191]\n",
      "\n",
      "Future exception was never retrieved\n",
      "future: <Future finished exception=ProtocolError('Connection aborted.', ConnectionResetError(10054, 'Se ha forzado la interrupción de una conexión existente por el host remoto', None, 10054, None))>\n",
      "Traceback (most recent call last):\n",
      "  File \"c:\\Users\\sersu\\anaconda3\\lib\\site-packages\\urllib3\\connectionpool.py\", line 703, in urlopen\n",
      "    httplib_response = self._make_request(\n",
      "  File \"c:\\Users\\sersu\\anaconda3\\lib\\site-packages\\urllib3\\connectionpool.py\", line 449, in _make_request\n",
      "    six.raise_from(e, None)\n",
      "  File \"<string>\", line 3, in raise_from\n",
      "  File \"c:\\Users\\sersu\\anaconda3\\lib\\site-packages\\urllib3\\connectionpool.py\", line 444, in _make_request\n",
      "    httplib_response = conn.getresponse()\n",
      "  File \"c:\\Users\\sersu\\anaconda3\\lib\\http\\client.py\", line 1377, in getresponse\n",
      "    response.begin()\n",
      "  File \"c:\\Users\\sersu\\anaconda3\\lib\\http\\client.py\", line 320, in begin\n",
      "    version, status, reason = self._read_status()\n",
      "  File \"c:\\Users\\sersu\\anaconda3\\lib\\http\\client.py\", line 281, in _read_status\n",
      "    line = str(self.fp.readline(_MAXLINE + 1), \"iso-8859-1\")\n",
      "  File \"c:\\Users\\sersu\\anaconda3\\lib\\socket.py\", line 704, in readinto\n",
      "    return self._sock.recv_into(b)\n",
      "ConnectionResetError: [WinError 10054] Se ha forzado la interrupción de una conexión existente por el host remoto\n",
      "\n",
      "During handling of the above exception, another exception occurred:\n",
      "\n",
      "Traceback (most recent call last):\n",
      "  File \"c:\\Users\\sersu\\anaconda3\\lib\\concurrent\\futures\\thread.py\", line 58, in run\n",
      "    result = self.fn(*self.args, **self.kwargs)\n",
      "  File \"C:\\Users\\sersu\\AppData\\Local\\Temp\\ipykernel_32012\\300363245.py\", line 7, in utmb\n",
      "    driver.get(utmb_url)\n",
      "  File \"c:\\Users\\sersu\\anaconda3\\lib\\site-packages\\selenium\\webdriver\\remote\\webdriver.py\", line 455, in get\n",
      "    self.execute(Command.GET, {\"url\": url})\n",
      "  File \"c:\\Users\\sersu\\anaconda3\\lib\\site-packages\\selenium\\webdriver\\remote\\webdriver.py\", line 442, in execute\n",
      "    response = self.command_executor.execute(driver_command, params)\n",
      "  File \"c:\\Users\\sersu\\anaconda3\\lib\\site-packages\\selenium\\webdriver\\remote\\remote_connection.py\", line 294, in execute\n",
      "    return self._request(command_info[0], url, body=data)\n",
      "  File \"c:\\Users\\sersu\\anaconda3\\lib\\site-packages\\selenium\\webdriver\\remote\\remote_connection.py\", line 316, in _request\n",
      "    response = self._conn.request(method, url, body=body, headers=headers)\n",
      "  File \"c:\\Users\\sersu\\anaconda3\\lib\\site-packages\\urllib3\\request.py\", line 78, in request\n",
      "    return self.request_encode_body(\n",
      "  File \"c:\\Users\\sersu\\anaconda3\\lib\\site-packages\\urllib3\\request.py\", line 170, in request_encode_body\n",
      "    return self.urlopen(method, url, **extra_kw)\n",
      "  File \"c:\\Users\\sersu\\anaconda3\\lib\\site-packages\\urllib3\\poolmanager.py\", line 376, in urlopen\n",
      "    response = conn.urlopen(method, u.request_uri, **kw)\n",
      "  File \"c:\\Users\\sersu\\anaconda3\\lib\\site-packages\\urllib3\\connectionpool.py\", line 785, in urlopen\n",
      "    retries = retries.increment(\n",
      "  File \"c:\\Users\\sersu\\anaconda3\\lib\\site-packages\\urllib3\\util\\retry.py\", line 550, in increment\n",
      "    raise six.reraise(type(error), error, _stacktrace)\n",
      "  File \"c:\\Users\\sersu\\anaconda3\\lib\\site-packages\\urllib3\\packages\\six.py\", line 769, in reraise\n",
      "    raise value.with_traceback(tb)\n",
      "  File \"c:\\Users\\sersu\\anaconda3\\lib\\site-packages\\urllib3\\connectionpool.py\", line 703, in urlopen\n",
      "    httplib_response = self._make_request(\n",
      "  File \"c:\\Users\\sersu\\anaconda3\\lib\\site-packages\\urllib3\\connectionpool.py\", line 449, in _make_request\n",
      "    six.raise_from(e, None)\n",
      "  File \"<string>\", line 3, in raise_from\n",
      "  File \"c:\\Users\\sersu\\anaconda3\\lib\\site-packages\\urllib3\\connectionpool.py\", line 444, in _make_request\n",
      "    httplib_response = conn.getresponse()\n",
      "  File \"c:\\Users\\sersu\\anaconda3\\lib\\http\\client.py\", line 1377, in getresponse\n",
      "    response.begin()\n",
      "  File \"c:\\Users\\sersu\\anaconda3\\lib\\http\\client.py\", line 320, in begin\n",
      "    version, status, reason = self._read_status()\n",
      "  File \"c:\\Users\\sersu\\anaconda3\\lib\\http\\client.py\", line 281, in _read_status\n",
      "    line = str(self.fp.readline(_MAXLINE + 1), \"iso-8859-1\")\n",
      "  File \"c:\\Users\\sersu\\anaconda3\\lib\\socket.py\", line 704, in readinto\n",
      "    return self._sock.recv_into(b)\n",
      "urllib3.exceptions.ProtocolError: ('Connection aborted.', ConnectionResetError(10054, 'Se ha forzado la interrupción de una conexión existente por el host remoto', None, 10054, None))\n",
      "Future exception was never retrieved\n",
      "future: <Future finished exception=ProtocolError('Connection aborted.', ConnectionResetError(10054, 'Se ha forzado la interrupción de una conexión existente por el host remoto', None, 10054, None))>\n",
      "Traceback (most recent call last):\n",
      "  File \"c:\\Users\\sersu\\anaconda3\\lib\\site-packages\\urllib3\\connectionpool.py\", line 703, in urlopen\n",
      "    httplib_response = self._make_request(\n",
      "  File \"c:\\Users\\sersu\\anaconda3\\lib\\site-packages\\urllib3\\connectionpool.py\", line 449, in _make_request\n",
      "    six.raise_from(e, None)\n",
      "  File \"<string>\", line 3, in raise_from\n",
      "  File \"c:\\Users\\sersu\\anaconda3\\lib\\site-packages\\urllib3\\connectionpool.py\", line 444, in _make_request\n",
      "    httplib_response = conn.getresponse()\n",
      "  File \"c:\\Users\\sersu\\anaconda3\\lib\\http\\client.py\", line 1377, in getresponse\n",
      "    response.begin()\n",
      "  File \"c:\\Users\\sersu\\anaconda3\\lib\\http\\client.py\", line 320, in begin\n",
      "    version, status, reason = self._read_status()\n",
      "  File \"c:\\Users\\sersu\\anaconda3\\lib\\http\\client.py\", line 281, in _read_status\n",
      "    line = str(self.fp.readline(_MAXLINE + 1), \"iso-8859-1\")\n",
      "  File \"c:\\Users\\sersu\\anaconda3\\lib\\socket.py\", line 704, in readinto\n",
      "    return self._sock.recv_into(b)\n",
      "ConnectionResetError: [WinError 10054] Se ha forzado la interrupción de una conexión existente por el host remoto\n",
      "\n",
      "During handling of the above exception, another exception occurred:\n",
      "\n",
      "Traceback (most recent call last):\n",
      "  File \"c:\\Users\\sersu\\anaconda3\\lib\\concurrent\\futures\\thread.py\", line 58, in run\n",
      "    result = self.fn(*self.args, **self.kwargs)\n",
      "  File \"C:\\Users\\sersu\\AppData\\Local\\Temp\\ipykernel_32012\\300363245.py\", line 7, in utmb\n",
      "    driver.get(utmb_url)\n",
      "  File \"c:\\Users\\sersu\\anaconda3\\lib\\site-packages\\selenium\\webdriver\\remote\\webdriver.py\", line 455, in get\n",
      "    self.execute(Command.GET, {\"url\": url})\n",
      "  File \"c:\\Users\\sersu\\anaconda3\\lib\\site-packages\\selenium\\webdriver\\remote\\webdriver.py\", line 442, in execute\n",
      "    response = self.command_executor.execute(driver_command, params)\n",
      "  File \"c:\\Users\\sersu\\anaconda3\\lib\\site-packages\\selenium\\webdriver\\remote\\remote_connection.py\", line 294, in execute\n",
      "    return self._request(command_info[0], url, body=data)\n",
      "  File \"c:\\Users\\sersu\\anaconda3\\lib\\site-packages\\selenium\\webdriver\\remote\\remote_connection.py\", line 316, in _request\n",
      "    response = self._conn.request(method, url, body=body, headers=headers)\n",
      "  File \"c:\\Users\\sersu\\anaconda3\\lib\\site-packages\\urllib3\\request.py\", line 78, in request\n",
      "    return self.request_encode_body(\n",
      "  File \"c:\\Users\\sersu\\anaconda3\\lib\\site-packages\\urllib3\\request.py\", line 170, in request_encode_body\n",
      "    return self.urlopen(method, url, **extra_kw)\n",
      "  File \"c:\\Users\\sersu\\anaconda3\\lib\\site-packages\\urllib3\\poolmanager.py\", line 376, in urlopen\n",
      "    response = conn.urlopen(method, u.request_uri, **kw)\n",
      "  File \"c:\\Users\\sersu\\anaconda3\\lib\\site-packages\\urllib3\\connectionpool.py\", line 785, in urlopen\n",
      "    retries = retries.increment(\n",
      "  File \"c:\\Users\\sersu\\anaconda3\\lib\\site-packages\\urllib3\\util\\retry.py\", line 550, in increment\n",
      "    raise six.reraise(type(error), error, _stacktrace)\n",
      "  File \"c:\\Users\\sersu\\anaconda3\\lib\\site-packages\\urllib3\\packages\\six.py\", line 769, in reraise\n",
      "    raise value.with_traceback(tb)\n",
      "  File \"c:\\Users\\sersu\\anaconda3\\lib\\site-packages\\urllib3\\connectionpool.py\", line 703, in urlopen\n",
      "    httplib_response = self._make_request(\n",
      "  File \"c:\\Users\\sersu\\anaconda3\\lib\\site-packages\\urllib3\\connectionpool.py\", line 449, in _make_request\n",
      "    six.raise_from(e, None)\n",
      "  File \"<string>\", line 3, in raise_from\n",
      "  File \"c:\\Users\\sersu\\anaconda3\\lib\\site-packages\\urllib3\\connectionpool.py\", line 444, in _make_request\n",
      "    httplib_response = conn.getresponse()\n",
      "  File \"c:\\Users\\sersu\\anaconda3\\lib\\http\\client.py\", line 1377, in getresponse\n",
      "    response.begin()\n",
      "  File \"c:\\Users\\sersu\\anaconda3\\lib\\http\\client.py\", line 320, in begin\n",
      "    version, status, reason = self._read_status()\n",
      "  File \"c:\\Users\\sersu\\anaconda3\\lib\\http\\client.py\", line 281, in _read_status\n",
      "    line = str(self.fp.readline(_MAXLINE + 1), \"iso-8859-1\")\n",
      "  File \"c:\\Users\\sersu\\anaconda3\\lib\\socket.py\", line 704, in readinto\n",
      "    return self._sock.recv_into(b)\n",
      "urllib3.exceptions.ProtocolError: ('Connection aborted.', ConnectionResetError(10054, 'Se ha forzado la interrupción de una conexión existente por el host remoto', None, 10054, None))\n"
     ]
    },
    {
     "name": "stderr",
     "output_type": "stream",
     "text": [
      "Future exception was never retrieved\n",
      "future: <Future finished exception=ProtocolError('Connection aborted.', ConnectionResetError(10054, 'Se ha forzado la interrupción de una conexión existente por el host remoto', None, 10054, None))>\n",
      "Traceback (most recent call last):\n",
      "  File \"c:\\Users\\sersu\\anaconda3\\lib\\site-packages\\urllib3\\connectionpool.py\", line 703, in urlopen\n",
      "    httplib_response = self._make_request(\n",
      "  File \"c:\\Users\\sersu\\anaconda3\\lib\\site-packages\\urllib3\\connectionpool.py\", line 449, in _make_request\n",
      "    six.raise_from(e, None)\n",
      "  File \"<string>\", line 3, in raise_from\n",
      "  File \"c:\\Users\\sersu\\anaconda3\\lib\\site-packages\\urllib3\\connectionpool.py\", line 444, in _make_request\n",
      "    httplib_response = conn.getresponse()\n",
      "  File \"c:\\Users\\sersu\\anaconda3\\lib\\http\\client.py\", line 1377, in getresponse\n",
      "    response.begin()\n",
      "  File \"c:\\Users\\sersu\\anaconda3\\lib\\http\\client.py\", line 320, in begin\n",
      "    version, status, reason = self._read_status()\n",
      "  File \"c:\\Users\\sersu\\anaconda3\\lib\\http\\client.py\", line 281, in _read_status\n",
      "    line = str(self.fp.readline(_MAXLINE + 1), \"iso-8859-1\")\n",
      "  File \"c:\\Users\\sersu\\anaconda3\\lib\\socket.py\", line 704, in readinto\n",
      "    return self._sock.recv_into(b)\n",
      "ConnectionResetError: [WinError 10054] Se ha forzado la interrupción de una conexión existente por el host remoto\n",
      "\n",
      "During handling of the above exception, another exception occurred:\n",
      "\n",
      "Traceback (most recent call last):\n",
      "  File \"c:\\Users\\sersu\\anaconda3\\lib\\concurrent\\futures\\thread.py\", line 58, in run\n",
      "    result = self.fn(*self.args, **self.kwargs)\n",
      "  File \"C:\\Users\\sersu\\AppData\\Local\\Temp\\ipykernel_32012\\300363245.py\", line 7, in utmb\n",
      "    driver.get(utmb_url)\n",
      "  File \"c:\\Users\\sersu\\anaconda3\\lib\\site-packages\\selenium\\webdriver\\remote\\webdriver.py\", line 455, in get\n",
      "    self.execute(Command.GET, {\"url\": url})\n",
      "  File \"c:\\Users\\sersu\\anaconda3\\lib\\site-packages\\selenium\\webdriver\\remote\\webdriver.py\", line 442, in execute\n",
      "    response = self.command_executor.execute(driver_command, params)\n",
      "  File \"c:\\Users\\sersu\\anaconda3\\lib\\site-packages\\selenium\\webdriver\\remote\\remote_connection.py\", line 294, in execute\n",
      "    return self._request(command_info[0], url, body=data)\n",
      "  File \"c:\\Users\\sersu\\anaconda3\\lib\\site-packages\\selenium\\webdriver\\remote\\remote_connection.py\", line 316, in _request\n",
      "    response = self._conn.request(method, url, body=body, headers=headers)\n",
      "  File \"c:\\Users\\sersu\\anaconda3\\lib\\site-packages\\urllib3\\request.py\", line 78, in request\n",
      "    return self.request_encode_body(\n",
      "  File \"c:\\Users\\sersu\\anaconda3\\lib\\site-packages\\urllib3\\request.py\", line 170, in request_encode_body\n",
      "    return self.urlopen(method, url, **extra_kw)\n",
      "  File \"c:\\Users\\sersu\\anaconda3\\lib\\site-packages\\urllib3\\poolmanager.py\", line 376, in urlopen\n",
      "    response = conn.urlopen(method, u.request_uri, **kw)\n",
      "  File \"c:\\Users\\sersu\\anaconda3\\lib\\site-packages\\urllib3\\connectionpool.py\", line 785, in urlopen\n",
      "    retries = retries.increment(\n",
      "  File \"c:\\Users\\sersu\\anaconda3\\lib\\site-packages\\urllib3\\util\\retry.py\", line 550, in increment\n",
      "    raise six.reraise(type(error), error, _stacktrace)\n",
      "  File \"c:\\Users\\sersu\\anaconda3\\lib\\site-packages\\urllib3\\packages\\six.py\", line 769, in reraise\n",
      "    raise value.with_traceback(tb)\n",
      "  File \"c:\\Users\\sersu\\anaconda3\\lib\\site-packages\\urllib3\\connectionpool.py\", line 703, in urlopen\n",
      "    httplib_response = self._make_request(\n",
      "  File \"c:\\Users\\sersu\\anaconda3\\lib\\site-packages\\urllib3\\connectionpool.py\", line 449, in _make_request\n",
      "    six.raise_from(e, None)\n",
      "  File \"<string>\", line 3, in raise_from\n",
      "  File \"c:\\Users\\sersu\\anaconda3\\lib\\site-packages\\urllib3\\connectionpool.py\", line 444, in _make_request\n",
      "    httplib_response = conn.getresponse()\n",
      "  File \"c:\\Users\\sersu\\anaconda3\\lib\\http\\client.py\", line 1377, in getresponse\n",
      "    response.begin()\n",
      "  File \"c:\\Users\\sersu\\anaconda3\\lib\\http\\client.py\", line 320, in begin\n",
      "    version, status, reason = self._read_status()\n",
      "  File \"c:\\Users\\sersu\\anaconda3\\lib\\http\\client.py\", line 281, in _read_status\n",
      "    line = str(self.fp.readline(_MAXLINE + 1), \"iso-8859-1\")\n",
      "  File \"c:\\Users\\sersu\\anaconda3\\lib\\socket.py\", line 704, in readinto\n",
      "    return self._sock.recv_into(b)\n",
      "urllib3.exceptions.ProtocolError: ('Connection aborted.', ConnectionResetError(10054, 'Se ha forzado la interrupción de una conexión existente por el host remoto', None, 10054, None))\n"
     ]
    }
   ],
   "source": [
    "'''utmb2022=utmb(2)\n",
    "utmb2021=utmb(3)\n",
    "utmb2019=utmb(4)\n",
    "utmb2018=utmb(5)\n",
    "utmb2017=utmb(6)\n",
    "utmb2016=utmb(7)\n",
    "utmb2015=utmb(8)\n",
    "utmb2014=utmb(9)\n",
    "utmb2013=utmb(10)\n",
    "utmb2012=utmb(11)\n",
    "utmb2011=utmb(12)\n",
    "utmb2009=utmb(14)\n",
    "utmb2008=utmb(15)\n",
    "utmb2007=utmb(16)\n",
    "utmb2006=utmb(17)\n",
    "utmb2005=utmb(18)\n",
    "utmb2004=utmb(19)'''"
   ]
  },
  {
   "cell_type": "code",
   "execution_count": 41,
   "metadata": {},
   "outputs": [],
   "source": [
    "'''utmb2021=utmb(3)\n",
    "utmb2019=utmb(4)\n",
    "utmb2013=utmb(10)\n",
    "'''"
   ]
  },
  {
   "cell_type": "code",
   "execution_count": 55,
   "metadata": {},
   "outputs": [],
   "source": [
    "columns=['clasificación','nombre_club', 'cat','clasificacion', 'tiempo', 'diferencia', 'nacionalidad']"
   ]
  },
  {
   "cell_type": "code",
   "execution_count": 43,
   "metadata": {},
   "outputs": [],
   "source": [
    "##Reseteamos los indices de todas\n",
    "\n",
    "utmb2022.reset_index(level=None, drop=False, inplace=True, col_level=0, col_fill='')\n",
    "utmb2021.reset_index(level=None, drop=False, inplace=True, col_level=0, col_fill='')\n",
    "utmb2019.reset_index(level=None, drop=False, inplace=True, col_level=0, col_fill='')\n",
    "utmb2018.reset_index(level=None, drop=False, inplace=True, col_level=0, col_fill='')\n",
    "utmb2017.reset_index(level=None, drop=False, inplace=True, col_level=0, col_fill='')\n",
    "utmb2016.reset_index(level=None, drop=False, inplace=True, col_level=0, col_fill='')\n",
    "utmb2015.reset_index(level=None, drop=False, inplace=True, col_level=0, col_fill='')\n",
    "utmb2014.reset_index(level=None, drop=False, inplace=True, col_level=0, col_fill='')\n",
    "utmb2013.reset_index(level=None, drop=False, inplace=True, col_level=0, col_fill='')\n",
    "utmb2012.reset_index(level=None, drop=False, inplace=True, col_level=0, col_fill='')\n",
    "utmb2011.reset_index(level=None, drop=False, inplace=True, col_level=0, col_fill='')\n",
    "utmb2009.reset_index(level=None, drop=False, inplace=True, col_level=0, col_fill='')\n",
    "utmb2008.reset_index(level=None, drop=False, inplace=True, col_level=0, col_fill='')\n",
    "utmb2007.reset_index(level=None, drop=False, inplace=True, col_level=0, col_fill='')\n",
    "utmb2006.reset_index(level=None, drop=False, inplace=True, col_level=0, col_fill='')\n",
    "utmb2005.reset_index(level=None, drop=False, inplace=True, col_level=0, col_fill='')\n",
    "utmb2004.reset_index(level=None, drop=False, inplace=True, col_level=0, col_fill='')\n",
    "\n"
   ]
  },
  {
   "cell_type": "code",
   "execution_count": 45,
   "metadata": {},
   "outputs": [],
   "source": [
    "##Las subimos a csv\n",
    "\n",
    "\n",
    "utmb2022.to_csv('data/utmb2022.csv',index=False)\n",
    "utmb2021.to_csv('data/utmb2021.csv',index=False)\n",
    "utmb2019.to_csv('data/utmb2019.csv',index=False)\n",
    "utmb2018.to_csv('data/utmb2018.csv',index=False)\n",
    "utmb2017.to_csv('data/utmb2017.csv',index=False)\n",
    "utmb2016.to_csv('data/utmb2016.csv',index=False)\n",
    "utmb2015.to_csv('data/utmb2015.csv',index=False)\n",
    "utmb2014.to_csv('data/utmb2014.csv',index=False)\n",
    "utmb2013.to_csv('data/utmb2013.csv',index=False)\n",
    "utmb2012.to_csv('data/utmb2012.csv',index=False)\n",
    "utmb2011.to_csv('data/utmb2011.csv',index=False)\n",
    "utmb2009.to_csv('data/utmb2009.csv',index=False)\n",
    "utmb2008.to_csv('data/utmb2008.csv',index=False)\n",
    "utmb2007.to_csv('data/utmb2007.csv',index=False)\n",
    "utmb2006.to_csv('data/utmb2006.csv',index=False)\n",
    "utmb2005.to_csv('data/utmb2005.csv',index=False)\n",
    "utmb2004.to_csv('data/utmb2004.csv',index=False)"
   ]
  },
  {
   "cell_type": "code",
   "execution_count": 68,
   "metadata": {},
   "outputs": [
    {
     "data": {
      "application/json": {
       "ascii": false,
       "bar_format": null,
       "colour": null,
       "elapsed": 0.010509729385375977,
       "initial": 0,
       "n": 0,
       "ncols": null,
       "nrows": null,
       "postfix": null,
       "prefix": "",
       "rate": null,
       "total": 4,
       "unit": "it",
       "unit_divisor": 1000,
       "unit_scale": false
      },
      "application/vnd.jupyter.widget-view+json": {
       "model_id": "0200c8c90732454db88017c7de79a705",
       "version_major": 2,
       "version_minor": 0
      },
      "text/plain": [
       "  0%|          | 0/4 [00:00<?, ?it/s]"
      ]
     },
     "metadata": {},
     "output_type": "display_data"
    },
    {
     "name": "stderr",
     "output_type": "stream",
     "text": [
      "[Parallel(n_jobs=6)]: Using backend LokyBackend with 6 concurrent workers.\n",
      "[Parallel(n_jobs=6)]: Done   4 out of   4 | elapsed:  2.0min finished\n"
     ]
    }
   ],
   "source": [
    "##Lo ejecutamos en paralelo y esta vez si funciona\n",
    "\n",
    "num_pag=[1,2,3,4]\n",
    "\n",
    "lst_df=Parallel(n_jobs=6, verbose=True)(delayed(meridiano)(num) for num in tqdm(num_pag))"
   ]
  },
  {
   "cell_type": "code",
   "execution_count": null,
   "metadata": {},
   "outputs": [],
   "source": [
    "utmb2022.to_excel('data/utmb2022.csv',index=False)\n",
    "utmb2021.to_excel('data/utmb2021.csv',index=False)\n",
    "utmb2019.to_excel('data/utmb2019.csv',index=False)\n",
    "utmb2018.to_excel('data/utmb2018.csv',index=False)\n",
    "utmb2017.to_excel('data/utmb2017.csv',index=False)\n",
    "utmb2016.to_excel('data/utmb2016.csv',index=False)\n",
    "utmb2015.to_excel('data/utmb2015.csv',index=False)\n",
    "utmb2014.to_excel('data/utmb2014.csv',index=False)\n",
    "utmb2013.to_excel('data/utmb2013.csv',index=False)\n",
    "utmb2012.to_excel('data/utmb2012.csv',index=False)\n",
    "utmb2011.to_excel('data/utmb2011.csv',index=False)\n",
    "utmb2009.to_excel('data/utmb2009.csv',index=False)\n",
    "utmb2008.to_excel('data/utmb2008.csv',index=False)\n",
    "utmb2007.to_excel('data/utmb2007.csv',index=False)\n",
    "utmb2006.to_excel('data/utmb2006.csv',index=False)\n",
    "utmb2005.to_excel('data/utmb2005.csv',index=False)\n",
    "utmb2004.to_excel('data/utmb2004.csv',index=False)"
   ]
  }
 ],
 "metadata": {
  "kernelspec": {
   "display_name": "Python 3.9.12 ('base')",
   "language": "python",
   "name": "python3"
  },
  "language_info": {
   "codemirror_mode": {
    "name": "ipython",
    "version": 3
   },
   "file_extension": ".py",
   "mimetype": "text/x-python",
   "name": "python",
   "nbconvert_exporter": "python",
   "pygments_lexer": "ipython3",
   "version": "3.9.12"
  },
  "orig_nbformat": 4,
  "vscode": {
   "interpreter": {
    "hash": "1551151381e773f0aad4d7f5dd85d557969b09f98d8f1647db122078155b292b"
   }
  }
 },
 "nbformat": 4,
 "nbformat_minor": 2
}
